Workbook
Name _4_FINAL_PERMITS_34_T: Dataset!$A$1:$X$4145

Sheet Dataset
A1: PTO_RECORD_ID | B1: PTO_STATUS | C1: OPEN_DATE | D1: EQUIPMENT_TYPE | E1: DBA | F1: PTO_CONTACT | G1: EQUIP_LOCATION_ADDRESS | H1: ZIP_CODE | I1: SECTOR | J1: PERMIT_DESCRIPTION | K1: Diesel | L1: Petroleum | M1: Natural Gas | N1: Propane | O1: Sum | P1: Fuel | Q1: Capacity listed (kW) | R1: Horsepower | S1: Total Capacity (kW) | T1: FIRST_READING_DT | U1: FIRST_READING_OF_YEAR | V1: LAST_READING_DT | W1: LAST_READING_OF_YEAR | X1: LAST READING - FIRST READING | Y1: Electricity Generation (kWh) | Z1: Estimated Emissions (tCO2) | AA1: Latitude | AB1: Longitude | AC1: Accuracy Score | AD1: Accuracy Type | AE1: Number | AF1: Street | AG1: Unit Type | AH1: Unit Number | AI1: City | AJ1: State | AK1: County | AL1: Zip | AM1: Country | AN1: Source
A2: APCD1995-PTO-890540 | B2: Active | C2: 40025 | D2: [34C] Emergency Standby Engine | E2: EMERALD PLAZA | G2: 402 BROADWAY W SAN DIEGO, CA | H2: 92101 | I2: N | J2: EMERGENCY GENERATOR: (1) KOHLER MODEL, 750 KW, DRIVEN BY A DETROIT DIESEL ENGINE, MODEL # 816317416, V-16, S/N 7A00049, ENGINE # 16vf008489, TURBOCHARGED, 1232 BHP (UNIT #FOO8489) 17CCR93115 SJE 11/05 (ATCM DATA: S/N 7A00049) | K2: =IFERROR(IF(SEARCH(K$1,$J2)>0,1),0) -> 1 | L2: =IFERROR(IF(SEARCH(L$1,$J2)>0,1),0) -> 0 | M2: =IFERROR(IF(SEARCH(M$1,$J2)>0,1),0) -> 0 | N2: =IFERROR(IF(SEARCH(N$1,$J2)>0,1),0) -> 0 | O2: =SUM(K2:N2) -> 1 | P2: Diesel | Q2: 750 | R2: 1232 | S2: =IFERROR(IF(ISBLANK(Q2)=FALSE,Q2,R2*0.7457),"Unknown") -> 750 | T2: 44497 | U2: 431.70 | V2: 44791 | W2: 445.20 | X2: 13.5 | Y2: =X2*S2 -> 10125 | Z2: =IFERROR(INDEX(EFs!B:B,MATCH(P2,EFs!A:A,0))*Dataset!Y2/1000,0) -> 9.1974783 | AA2: 32.715933 | AB2: -117.16084 | AC2: 1 | AD2: rooftop | AE2: 402 | AF2: Broadway | AI2: San Diego | AJ2: CA | AK2: San Diego County | AL2: 92101 | AM2: US | AN2: San Diego Geographic Information Source - JPA
A3: APCD1998-PTO-960036 | B3: Active | C3: 40025 | D3: [34W] Registered Engine (Rule 12) | E3: Ramona Municipal Water District | F3: Facility Manager | G3: 260 Sawday St Ramona, CA | H3: 92065 | I3: F | J3: EMERGENCY STANDBY ENGINE: INTERNATIONAL-HARVESTER ENGINE, MODEL V-549,S/N 145136850KR-15R, 172 BHP, PROPANE-FIRED, DRIVING AN ONAN GENERATOR. (960036-CCN-2/98) | K3: =IFERROR(IF(SEARCH(K$1,$J3)>0,1),0) -> 0 | L3: =IFERROR(IF(SEARCH(L$1,$J3)>0,1),0) -> 0 | M3: =IFERROR(IF(SEARCH(M$1,$J3)>0,1),0) -> 0 | N3: =IFERROR(IF(SEARCH(N$1,$J3)>0,1),0) -> 1 | O3: =SUM(K3:N3) -> 1 | P3: Propane | R3: 172 | S3: =IFERROR(IF(Q3<>"",Q3,R3*0.7457),"Unknown") -> 128.2604 | T3: 44532 | U3: 747.80 | V3: 44532 | W3: 754.20 | X3: 6.4 | Y3: =X3*S3 -> 820.86656 | Z3: =IFERROR(INDEX(EFs!B:B,MATCH(P3,EFs!A:A,0))*Dataset!Y3/1000,0) -> 0.67631196 | AA3: 33.029999 | AB3: -116.9007 | AC3: 1 | AD3: range_interpolation | AE3: 260 | AF3: Sawday St | AI3: Ramona | AJ3: CA | AK3: San Diego County | AL3: 92065 | AM3: US | AN3: TIGER/LineÂ® dataset from the US Census Bureau
A4: APCD1998-PTO-960492 | B4: Active | C4: 40025 | D4: [34W] Registered Engine (Rule 12) | E4: UCSD Elliot Field | F4: Valerie Fanning | G4: 10205 Pomerado Road San Diego, CA | H4: 92131 | I4: F | J4: Registration of Stationary Emergency Stand-by Engine_x000D_IHC, Model: UV549, S/N: V-549-3960KOCLQ1, 100 hp, Fuel: Natural Gas_x000D_Year operated in San Diego County: 1997 _x000D_APCD2009-CER-000077/SH 16-Feb-2010 | K4: =IFERROR(IF(SEARCH(K$1,$J4)>0,1),0) -> 0 | L4: =IFERROR(IF(SEARCH(L$1,$J4)>0,1),0) -> 0 | M4: =IFERROR(IF(SEARCH(M$1,$J4)>0,1),0) -> 1 | N4: =IFERROR(IF(SEARCH(N$1,$J4)>0,1),0) -> 0 | O4: =SUM(K4:N4) -> 1 | P4: Natural Gas | R4: 100 | S4: =IFERROR(IF(Q4<>"",Q4,R4*0.7457),"Unknown") -> 74.57 | T4: 44376 | U4: 950.40 | V4: 44764 | W4: 950.40 | X4: 0 | Y4: =X4*S4 -> 0 | Z4: =IFERROR(INDEX(EFs!B:B,MATCH(P4,EFs!A:A,0))*Dataset!Y4/1000,0) -> 0 | AA4: 32.895794 | AB4: -117.1072 | AC4: 1 | AD4: range_interpolation | AE4: 10205 | AF4: Pomerado Rd | AI4: San Diego | AJ4: CA | AK4: San Diego County | AL4: 92131 | AM4: US | AN4: TIGER/LineÂ® dataset from the US Census Bureau
A5: APCD1998-PTO-961717 | B5: Active | C5: 40025 | D5: [34W] Registered Engine (Rule 12) | E5: Sea World San Diego | F5: Steve Melanese | G5: 500 Sea World Dr San Diego, CA | H5: 92109 | I5: I | J5: EMERGENCY STANDBY ENGINE: GENERAC MODEL 74GN, S/N 2029404, 160 BHP, NATURAL GAS FUELED. (961717-CCN-3/98) | K5: =IFERROR(IF(SEARCH(K$1,$J5)>0,1),0) -> 0 | L5: =IFERROR(IF(SEARCH(L$1,$J5)>0,1),0) -> 0 | M5: =IFERROR(IF(SEARCH(M$1,$J5)>0,1),0) -> 1 | N5: =IFERROR(IF(SEARCH(N$1,$J5)>0,1),0) -> 0 | O5: =SUM(K5:N5) -> 1 | P5: Natural Gas | R5: 160 | S5: =IFERROR(IF(Q5<>"",Q5,R5*0.7457),"Unknown") -> 119.312 | Y5: =X5*S5 -> 0 | Z5: =IFERROR(INDEX(EFs!B:B,MATCH(P5,EFs!A:A,0))*Dataset!Y5/1000,0) -> 0 | AA5: 32.761102 | AB5: -117.22194 | AC5: 1 | AD5: range_interpolation | AE5: 500 | AF5: Sea World Dr | AI5: San Diego | AJ5: CA | AK5: San Diego County | AL5: 92109 | AM5: US | AN5: TIGER/LineÂ® dataset from the US Census Bureau
A6: APCD1999-PTO-972305 | B6: Active | C6: 40025 | D6: [34W] Registered Engine (Rule 12) | E6: USN FASOTRAGRUPAC | F6: Commanding Officer | G6: 34567 Hwy 79 South Warner Springs, CA | H6: 92086 | I6: B | J6: EMERGENCY ENGINE GENERATOR: 207 HORSEPOWER CUMMINS MODEL G855 PROPANE ENGINE SERIAL NUMBER 25192953. 972305 GDS 2/99 | K6: =IFERROR(IF(SEARCH(K$1,$J6)>0,1),0) -> 0 | L6: =IFERROR(IF(SEARCH(L$1,$J6)>0,1),0) -> 0 | M6: =IFERROR(IF(SEARCH(M$1,$J6)>0,1),0) -> 0 | N6: =IFERROR(IF(SEARCH(N$1,$J6)>0,1),0) -> 1 | O6: =SUM(K6:N6) -> 1 | P6: Propane | R6: 207 | S6: =IFERROR(IF(Q6<>"",Q6,R6*0.7457),"Unknown") -> 154.3599 | T6: 44404 | U6: 846.20 | V6: 44739 | W6: 949.20 | X6: 103 | Y6: =X6*S6 -> 15899.07 | Z6: =IFERROR(INDEX(EFs!B:B,MATCH(P6,EFs!A:A,0))*Dataset!Y6/1000,0) -> 13.099244 | AA6: 33.338921 | AB6: -116.71941 | AC6: 1 | AD6: range_interpolation | AE6: 34567 | AF6: Hwy 79 | AI6: Warner Springs | AJ6: CA | AK6: San Diego County | AL6: 92086 | AM6: US | AN6: TIGER/LineÂ® dataset from the US Census Bureau
A7: APCD2000-PTO-961607 | B7: Active | C7: 40025 | D7: [34W] Registered Engine (Rule 12) | E7: San Diego State University | F7: Lilly Sabet | G7: 5500 Campanile Dr San Diego, CA | H7: 92182 | I7: K | J7: EMERGENCY STANDBY ENGINE: FORD MODEL CSG-6491, S/N 25043-616KR, 82 BHP, NATURAL GAS FUELED, LOCATED AT THE LOVE LIBRARY. (961606-CCN-3/98) | K7: =IFERROR(IF(SEARCH(K$1,$J7)>0,1),0) -> 0 | L7: =IFERROR(IF(SEARCH(L$1,$J7)>0,1),0) -> 0 | M7: =IFERROR(IF(SEARCH(M$1,$J7)>0,1),0) -> 1 | N7: =IFERROR(IF(SEARCH(N$1,$J7)>0,1),0) -> 0 | O7: =SUM(K7:N7) -> 1 | P7: Natural Gas | R7: 82 | S7: =IFERROR(IF(Q7<>"",Q7,R7*0.7457),"Unknown") -> 61.1474 | T7: 44490 | U7: 2850.00 | V7: 44490 | W7: 2855.20 | X7: 5.2 | Y7: =X7*S7 -> 317.96648 | Z7: =IFERROR(INDEX(EFs!B:B,MATCH(P7,EFs!A:A,0))*Dataset!Y7/1000,0) -> 0.23092497 | AA7: 32.772147 | AB7: -117.07255 | AC7: 1 | AD7: rooftop | AE7: 5500 | AF7: Campanile Dr | AI7: San Diego | AJ7: CA | AK7: San Diego County | AL7: 92182 | AM7: US | AN7: San Diego Geographic Information Source - JPA
A8: APCD2000-PTO-961608 | B8: Active | C8: 40025 | D8: [34W] Registered Engine (Rule 12) | E8: San Diego State University | F8: Lilly Sabet | G8: 5500 Campanile Dr San Diego, CA | H8: 92182 | I8: K | J8: EMERGENCY STANDBY ENGINE: FORD MODEL CSG-6491, 82 BHP, NATURAL GAS FUELED, LOCATED IN THE NEW ART BUILDING. S/N 13670. (961608-CCN-3/98) | K8: =IFERROR(IF(SEARCH(K$1,$J8)>0,1),0) -> 0 | L8: =IFERROR(IF(SEARCH(L$1,$J8)>0,1),0) -> 0 | M8: =IFERROR(IF(SEARCH(M$1,$J8)>0,1),0) -> 1 | N8: =IFERROR(IF(SEARCH(N$1,$J8)>0,1),0) -> 0 | O8: =SUM(K8:N8) -> 1 | P8: Natural Gas | R8: 82 | S8: =IFERROR(IF(Q8<>"",Q8,R8*0.7457),"Unknown") -> 61.1474 | T8: 44490 | U8: 3562.90 | V8: 44490 | W8: 3568.20 | X8: 5.3 | Y8: =X8*S8 -> 324.08122 | Z8: =IFERROR(INDEX(EFs!B:B,MATCH(P8,EFs!A:A,0))*Dataset!Y8/1000,0) -> 0.23536584 | AA8: 32.772147 | AB8: -117.07255 | AC8: 1 | AD8: rooftop | AE8: 5500 | AF8: Campanile Dr | AI8: San Diego | AJ8: CA | AK8: San Diego County | AL8: 92182 | AM8: US | AN8: San Diego Geographic Information Source - JPA
A9: APCD2001-PTO-961873 | B9: Active | C9: 40025 | D9: [34W] Registered Engine (Rule 12) | E9: Fairbanks Ranch Community SVC DIST | F9: General Manager | G9: 16556 Circa del Norte Rancho Santa Fe, CA | H9: 92067 | I9: E | J9: EMERGENCY ENGINE GENERATOR, 102 HP JOHN DEERE DIESEL ENGINE, MODEL 4039-TF, S/N CD 4039T186943, TURBOCHARGED, APPL# 961873 EFH 05/99 | K9: =IFERROR(IF(SEARCH(K$1,$J9)>0,1),0) -> 1 | L9: =IFERROR(IF(SEARCH(L$1,$J9)>0,1),0) -> 0 | M9: =IFERROR(IF(SEARCH(M$1,$J9)>0,1),0) -> 0 | N9: =IFERROR(IF(SEARCH(N$1,$J9)>0,1),0) -> 0 | O9: =SUM(K9:N9) -> 1 | P9: Diesel | R9: 102 | S9: =IFERROR(IF(Q9<>"",Q9,R9*0.7457),"Unknown") -> 76.0614 | T9: 44562 | U9: 214.30 | V9: 44562 | W9: 224.90 | X9: 10.6 | Y9: =X9*S9 -> 806.25084 | Z9: =IFERROR(INDEX(EFs!B:B,MATCH(P9,EFs!A:A,0))*Dataset!Y9/1000,0) -> 0.73239256 | AA9: 32.998916 | AB9: -117.1908 | AC9: 1 | AD9: rooftop | AE9: 16556 | AF9: Circa Del Norte | AI9: Rancho Santa Fe | AJ9: CA | AK9: San Diego County | AL9: 92067 | AM9: US | AN9: San Diego Geographic Information Source - JPA
A10: APCD2002-PTO-940514 | B10: Active | C10: 40025 | D10: [34C] Emergency Standby Engine | E10: Sweetwater Authority Water District | F10: Plant Maint Super | G10: 3066 N Second Av Chula Vista, CA | H10: 91910 | I10: Q | J10: EMERGENCY ENGINE GENERATOR SET: CUMMINS ENGINE, PROPANE GAS FIRED, MODEL WSG-1068, RATED AT 131.6 BHP, MODEL YEAR 2012, S/N 121150134, EPA ENGINE FAMILY NUMBER: CCEXB06.8GDB , WITH AN AIR FUEL RATIO CONTROLLER AND A THREE-WAY CATALYST CLOSED LOOP SYSTEM, ENGINE POWERS A 85 KW GENERATOR. | K10: =IFERROR(IF(SEARCH(K$1,$J10)>0,1),0) -> 0 | L10: =IFERROR(IF(SEARCH(L$1,$J10)>0,1),0) -> 0 | M10: =IFERROR(IF(SEARCH(M$1,$J10)>0,1),0) -> 0 | N10: =IFERROR(IF(SEARCH(N$1,$J10)>0,1),0) -> 1 | O10: =SUM(K10:N10) -> 1 | P10: Propane | Q10: 85 | R10: 131.6 | S10: =IFERROR(IF(Q10<>"",Q10,R10*0.7457),"Unknown") -> 85 | T10: 44491 | U10: 50.20 | V10: 44491 | W10: 52.40 | X10: 2.2 | Y10: =X10*S10 -> 187 | Z10: =IFERROR(INDEX(EFs!B:B,MATCH(P10,EFs!A:A,0))*Dataset!Y10/1000,0) -> 0.1540693 | AA10: 32.65953 | AB10: -117.08502 | AC10: 1 | AD10: rooftop | AE10: 3066 | AF10: N 2nd Ave | AI10: Chula Vista | AJ10: CA | AK10: San Diego County | AL10: 91910 | AM10: US | AN10: Sandoval
A11: APCD2002-PTO-960515 | B11: Active | C11: 40025 | D11: [34W] Registered Engine (Rule 12) | E11: Fleet Readiness Center Southwest | G11: NAS North Island San Diego, CA | H11: 92135 | I11: O | J11: EMERGENCY STANDBY ENGINE, CHRYSLER MODEL LH-318; S/N E-574874; 187 BHP, NATURAL GAS FIRED. APPL 960515 EFH 09/98 REVISION DATE 6-1-02 | K11: =IFERROR(IF(SEARCH(K$1,$J11)>0,1),0) -> 0 | L11: =IFERROR(IF(SEARCH(L$1,$J11)>0,1),0) -> 0 | M11: =IFERROR(IF(SEARCH(M$1,$J11)>0,1),0) -> 1 | N11: =IFERROR(IF(SEARCH(N$1,$J11)>0,1),0) -> 0 | O11: =SUM(K11:N11) -> 1 | P11: Natural Gas | R11: 187 | S11: =IFERROR(IF(Q11<>"",Q11,R11*0.7457),"Unknown") -> 139.4459 | Y11: =X11*S11 -> 0 | Z11: =IFERROR(INDEX(EFs!B:B,MATCH(P11,EFs!A:A,0))*Dataset!Y11/1000,0) -> 0 | AA11: 33.232765 | AB11: -117.35203 | AC11: 0.8 | AD11: street_center | AF11: New Branch Ct | AI11: Oceanside | AJ11: CA | AK11: San Diego County | AL11: 92058 | AM11: US | AN11: TIGER/LineÂ® dataset from the US Census Bureau
A12: APCD2002-PTO-975748 | B12: Active | C12: 40025 | D12: [34W] Registered Engine (Rule 12) | E12: Rancho Calevero Mobile Home Park | F12: General Manager | G12: 3527 Calevero Ln Oceanside, CA | H12: 92056 | I12: C | J12: FORD NATURAL GAS ENGINE, MODEL LSG-875, S/N 2202610498, 132 HP. _x000D_975748AFS22NOV2000 | K12: =IFERROR(IF(SEARCH(K$1,$J12)>0,1),0) -> 0 | L12: =IFERROR(IF(SEARCH(L$1,$J12)>0,1),0) -> 0 | M12: =IFERROR(IF(SEARCH(M$1,$J12)>0,1),0) -> 1 | N12: =IFERROR(IF(SEARCH(N$1,$J12)>0,1),0) -> 0 | O12: =SUM(K12:N12) -> 1 | P12: Natural Gas | R12: 132 | S12: =IFERROR(IF(Q12<>"",Q12,R12*0.7457),"Unknown") -> 98.4324 | T12: 44504 | U12: 66.10 | V12: 44504 | W12: 82.20 | X12: 16.1 | Y12: =X12*S12 -> 1584.7616 | Z12: =IFERROR(INDEX(EFs!B:B,MATCH(P12,EFs!A:A,0))*Dataset!Y12/1000,0) -> 1.1509422 | AA12: 33.17894 | AB12: -117.27982 | AC12: 1 | AD12: range_interpolation | AE12: 3527 | AF12: Calevero Ln | AI12: Oceanside | AJ12: CA | AK12: San Diego County | AL12: 92056 | AM12: US | AN12: TIGER/LineÂ® dataset from the US Census Bureau
A13: APCD2002-PTO-975755 | B13: Active | C13: 40025 | D13: [34W] Registered Engine (Rule 12) | E13: Clear Channel Communications | F13: Attn: Engineering | G13: 9660 Granite Ridge Dr San Diego, CA | H13: 92123 | I13: J | J13: EMERGENCY ENGINE GENERATOR, 755 HP, CUMMINS ENGINE, MODEL KTA19-G4, S/N 37195425, DRIVING ONAN CORPORATION GENERATOR, MODEL 500DFED, S/N J000164625. _x000D_APPL# 975755 EFH 04/01 (17CCR93115) SJE 10/05 | K13: =IFERROR(IF(SEARCH(K$1,$J13)>0,1),0) -> 0 | L13: =IFERROR(IF(SEARCH(L$1,$J13)>0,1),0) -> 0 | M13: =IFERROR(IF(SEARCH(M$1,$J13)>0,1),0) -> 0 | N13: =IFERROR(IF(SEARCH(N$1,$J13)>0,1),0) -> 0 | O13: =SUM(K13:N13) -> 0 | P13: Unknown | R13: 755 | S13: =IFERROR(IF(Q13<>"",Q13,R13*0.7457),"Unknown") -> 563.0035 | T13: 44562 | U13: 128.80 | V13: 44562 | W13: 137.40 | X13: 8.6 | Y13: =X13*S13 -> 4841.8301 | Z13: =IFERROR(INDEX(EFs!B:B,MATCH(P13,EFs!A:A,0))*Dataset!Y13/1000,0) -> 0 | AA13: 32.806873 | AB13: -117.12092 | AC13: 1 | AD13: rooftop | AE13: 9660 | AF13: Granite Ridge Dr | AI13: San Diego | AJ13: CA | AK13: San Diego County | AL13: 92123 | AM13: US | AN13: San Diego Geographic Information Source - JPA
A14: APCD2002-PTO-975914 | B14: Active | C14: 40025 | D14: [34W] Registered Engine (Rule 12) | E14: Dixieline Lumber Co | F14: Dennis McComb | G14: 3250 Sports Arena Blvd. San Diego, CA | H14: 92110 | I14: I | J14: EMERGENCY ENGINE: FORD, MODEL CSG 649I6005F, NATURAL GAS FIRED, 82 BHP, S/N 263731-0498, DRIVING AN ELECTRIC GENERATOR. (975914 ALC 01/01) | K14: =IFERROR(IF(SEARCH(K$1,$J14)>0,1),0) -> 0 | L14: =IFERROR(IF(SEARCH(L$1,$J14)>0,1),0) -> 0 | M14: =IFERROR(IF(SEARCH(M$1,$J14)>0,1),0) -> 1 | N14: =IFERROR(IF(SEARCH(N$1,$J14)>0,1),0) -> 0 | O14: =SUM(K14:N14) -> 1 | P14: Natural Gas | R14: 82 | S14: =IFERROR(IF(Q14<>"",Q14,R14*0.7457),"Unknown") -> 61.1474 | T14: 44558 | U14: 844.00 | V14: 44558 | W14: 875.60 | X14: 31.6 | Y14: =X14*S14 -> 1932.2578 | Z14: =IFERROR(INDEX(EFs!B:B,MATCH(P14,EFs!A:A,0))*Dataset!Y14/1000,0) -> 1.4033133 | AA14: 32.753524 | AB14: -117.2084 | AC14: 1 | AD14: rooftop | AE14: 3250 | AF14: Sports Arena Blvd | AI14: San Diego | AJ14: CA | AK14: San Diego County | AL14: 92110 | AM14: US | AN14: San Diego Geographic Information Source - JPA
A15: APCD2002-PTO-976373 | B15: Active | C15: 40025 | D15: [34W] Registered Engine (Rule 12) | E15: SD City Of Metro Wastewater Dept | G15: 3001 Ingraham ST San Diego, CA | H15: 92109 | I15: I | J15: INTERNAL COMBUSTION ENGINE. MAKE: HERCULES, MODEL: G2300. SERIAL NR.: IA3335652 G2300X210. HP RATING= 60, NATURAL GAS FUELED. SERVES AS AN EMERGENCY POWER SUPPLY. | K15: =IFERROR(IF(SEARCH(K$1,$J15)>0,1),0) -> 0 | L15: =IFERROR(IF(SEARCH(L$1,$J15)>0,1),0) -> 0 | M15: =IFERROR(IF(SEARCH(M$1,$J15)>0,1),0) -> 1 | N15: =IFERROR(IF(SEARCH(N$1,$J15)>0,1),0) -> 0 | O15: =SUM(K15:N15) -> 1 | P15: Natural Gas | R15: 60 | S15: =IFERROR(IF(Q15<>"",Q15,R15*0.7457),"Unknown") -> 44.742 | Y15: =X15*S15 -> 0 | Z15: =IFERROR(INDEX(EFs!B:B,MATCH(P15,EFs!A:A,0))*Dataset!Y15/1000,0) -> 0 | AA15: 32.773314 | AB15: -117.2347 | AC15: 1 | AD15: range_interpolation | AE15: 3001 | AF15: Ingraham St | AI15: San Diego | AJ15: CA | AK15: San Diego County | AL15: 92109 | AM15: US | AN15: TIGER/LineÂ® dataset from the US Census Bureau
A16: APCD2002-PTO-977230 | B16: Active | C16: 40025 | D16: [34C] Emergency Standby Engine | E16: San Diego State University | F16: Lilly Sabet | G16: 5500 Campanile Dr San Diego, CA | H16: 92182 | I16: K | J16: EMERGENCY STANDBY ENGINE: GENERAL MOTORS ENGINE, FUELED WITH NATURAL GAS, MODEL INDUSTRIAL POWER TRAIN, S/N 05882, 162 BHP, EQUIPPED WITH THREE-WAY CATALYTIC CONVERTER BANDITO MODEL CX-8-6, DRIVING A 121 KW GENERATOR, (977230-CCN-4/02) LOCATED AT TENOCHCA HALL. | K16: =IFERROR(IF(SEARCH(K$1,$J16)>0,1),0) -> 0 | L16: =IFERROR(IF(SEARCH(L$1,$J16)>0,1),0) -> 0 | M16: =IFERROR(IF(SEARCH(M$1,$J16)>0,1),0) -> 1 | N16: =IFERROR(IF(SEARCH(N$1,$J16)>0,1),0) -> 0 | O16: =SUM(K16:N16) -> 1 | P16: Natural Gas | Q16: 121 | R16: 162 | S16: =IFERROR(IF(Q16<>"",Q16,R16*0.7457),"Unknown") -> 121 | T16: 44495 | U16: 553.60 | V16: 44495 | W16: 558.70 | X16: 5.1 | Y16: =X16*S16 -> 617.1 | Z16: =IFERROR(INDEX(EFs!B:B,MATCH(P16,EFs!A:A,0))*Dataset!Y16/1000,0) -> 0.4481724 | AA16: 32.772147 | AB16: -117.07255 | AC16: 1 | AD16: rooftop | AE16: 5500 | AF16: Campanile Dr | AI16: San Diego | AJ16: CA | AK16: San Diego County | AL16: 92182 | AM16: US | AN16: San Diego Geographic Information Source - JPA
A17: APCD2002-PTO-977306 | B17: Active | C17: 40025 | D17: [34W] Registered Engine (Rule 12) | E17: Target Store T1040 | F17: General Manager | G17: 1751 University Dr Vista, CA | H17: 92083 | I17: C | J17: INTERNAL COMBUSTION ENGINE. MAKE: FORD; MODEL: CSG-6491-6005A. SERIAL NR.: 15408 H-08-RX. HP RATING=53. MANUFACTURE YEAR: AUGUST 1996. ENGINE OPERATES WITH NATURAL GAS WITH PROPANE AS BACK UP. EMERGENCY STANDBY POWER 35 KW GENERATION UNIT. | K17: =IFERROR(IF(SEARCH(K$1,$J17)>0,1),0) -> 0 | L17: =IFERROR(IF(SEARCH(L$1,$J17)>0,1),0) -> 0 | M17: =IFERROR(IF(SEARCH(M$1,$J17)>0,1),0) -> 1 | N17: =IFERROR(IF(SEARCH(N$1,$J17)>0,1),0) -> 1 | O17: =SUM(K17:N17) -> 2 | P17: Natural Gas | Q17: 35 | R17: 53 | S17: =IFERROR(IF(Q17<>"",Q17,R17*0.7457),"Unknown") -> 35 | T17: 44426 | U17: 242.70 | V17: 44426 | W17: 248.30 | X17: 5.6 | Y17: =X17*S17 -> 196 | Z17: =IFERROR(INDEX(EFs!B:B,MATCH(P17,EFs!A:A,0))*Dataset!Y17/1000,0) -> 0.14234612 | AA17: 33.169267 | AB17: -117.21487 | AC17: 1 | AD17: rooftop | AE17: 1751 | AF17: University Dr | AI17: Vista | AJ17: CA | AK17: San Diego County | AL17: 92083 | AM17: US | AN17: San Diego Geographic Information Source - JPA
A18: APCD2002-PTO-978134 | B18: Active | C18: 40025 | D18: [34C] Emergency Standby Engine | E18: SD CO OF DPW WASTEWATER MGMT DIV | F18: PLANT OPERATOR | G18: 215 BRIDLE RUN CT ALPINE, CA | H18: 91901 | I18: H | J18: EMERGENCY STANDBY ENGINE: GENERAL MOTORS MODEL VORTEC 8.1L, 150 HP, NATURAL GAS FIRED, ENGINE S/N 8.1L-05682, YEAR OF MANUFACTURE 2001; GENERATOR S/N 0720529, 80 KW. 978134AFS31OCT2002 | K18: =IFERROR(IF(SEARCH(K$1,$J18)>0,1),0) -> 0 | L18: =IFERROR(IF(SEARCH(L$1,$J18)>0,1),0) -> 0 | M18: =IFERROR(IF(SEARCH(M$1,$J18)>0,1),0) -> 1 | N18: =IFERROR(IF(SEARCH(N$1,$J18)>0,1),0) -> 0 | O18: =SUM(K18:N18) -> 1 | P18: Natural Gas | Q18: 80 | R18: 150 | S18: =IFERROR(IF(Q18<>"",Q18,R18*0.7457),"Unknown") -> 80 | T18: 44562 | U18: 303.70 | V18: 44562 | W18: 304.60 | X18: 0.9 | Y18: =X18*S18 -> 72 | Z18: =IFERROR(INDEX(EFs!B:B,MATCH(P18,EFs!A:A,0))*Dataset!Y18/1000,0) -> 0.052290412 | AA18: 32.833802 | AB18: -116.81834 | AC18: 1 | AD18: rooftop | AE18: 215 | AF18: Bridle Run Ct | AI18: Alpine | AJ18: CA | AK18: San Diego County | AL18: 91901 | AM18: US | AN18: Sandoval
A19: APCD2002-PTO-978485 | B19: Active | C19: 40025 | D19: [34C] Emergency Standby Engine | E19: Albertsons #3797 | F19: Jill Washburn | G19: 1601 S Melrose Dr Vista, CA | H19: 92081 | I19: B | J19: EMERGENCY ENGINE: GENERAL MOTORS, MODEL VORTEC 4.3LG, 75 BHP, NATURAL GAS FIRED, S/N 715085, DRIVING A 45-KW KOHLER MODEL 30RZG ELECTRIC GENERATOR. (978485 ALC 09/02) | K19: =IFERROR(IF(SEARCH(K$1,$J19)>0,1),0) -> 0 | L19: =IFERROR(IF(SEARCH(L$1,$J19)>0,1),0) -> 0 | M19: =IFERROR(IF(SEARCH(M$1,$J19)>0,1),0) -> 1 | N19: =IFERROR(IF(SEARCH(N$1,$J19)>0,1),0) -> 0 | O19: =SUM(K19:N19) -> 1 | P19: Natural Gas | Q19: 45 | R19: 75 | S19: =IFERROR(IF(Q19<>"",Q19,R19*0.7457),"Unknown") -> 45 | T19: 44540 | U19: 370.10 | V19: 44540 | W19: 387.20 | X19: 17.1 | Y19: =X19*S19 -> 769.5 | Z19: =IFERROR(INDEX(EFs!B:B,MATCH(P19,EFs!A:A,0))*Dataset!Y19/1000,0) -> 0.55885378 | AA19: 33.165545 | AB19: -117.24744 | AC19: 1 | AD19: rooftop | AE19: 1601 | AF19: S Melrose Dr S | AI19: Vista | AJ19: CA | AK19: San Diego County | AL19: 92081 | AM19: US | AN19: San Diego Geographic Information Source - JPA
A20: APCD2002-PTO-978614 | B20: Active | C20: 40025 | D20: [34C] Emergency Standby Engine | E20: City of Escondido - LS#05 | G20: 735 Opper Street Escondido, CA | H20: 92029 | I20: D | J20: EMERGENCY STANDBY ENGINE: GENERAL MOTORS MODEL 4.3L, 72 HP, LIQUID PROPANE FIRED, S/N 4.3L-14384, 35 KW GENERATOR. | K20: =IFERROR(IF(SEARCH(K$1,$J20)>0,1),0) -> 0 | L20: =IFERROR(IF(SEARCH(L$1,$J20)>0,1),0) -> 0 | M20: =IFERROR(IF(SEARCH(M$1,$J20)>0,1),0) -> 0 | N20: =IFERROR(IF(SEARCH(N$1,$J20)>0,1),0) -> 1 | O20: =SUM(K20:N20) -> 1 | P20: Propane | Q20: 35 | R20: 72 | S20: =IFERROR(IF(Q20<>"",Q20,R20*0.7457),"Unknown") -> 35 | T20: 44393 | U20: 411.10 | V20: 44393 | W20: 416.80 | X20: 5.7 | Y20: =X20*S20 -> 199.5 | Z20: =IFERROR(INDEX(EFs!B:B,MATCH(P20,EFs!A:A,0))*Dataset!Y20/1000,0) -> 0.16436805 | AA20: 33.131152 | AB20: -117.12637 | AC20: 1 | AD20: range_interpolation | AE20: 735 | AF20: Opper St | AI20: Escondido | AJ20: CA | AK20: San Diego County | AL20: 92029 | AM20: US | AN20: TIGER/LineÂ® dataset from the US Census Bureau
A21: APCD2003-PTO-971023 | B21: Active | C21: 40025 | D21: [34W] Registered Engine (Rule 12) | E21: USMC Base Navy Sea Ops | F21: Air Quality Section | G21: Building 31930 Camp Pendleton, CA | H21: 92055 | I21: A | J21: EMERGENCY ENGINE: FORD MODEL CSG-6491-6005-F, PROPANE FIRED, 82 HP, S/N 23887 E-11-RH, DRIVING AN ELECTRIC GENERATOR, LOCATED IN BLDG #31930 | K21: =IFERROR(IF(SEARCH(K$1,$J21)>0,1),0) -> 0 | L21: =IFERROR(IF(SEARCH(L$1,$J21)>0,1),0) -> 0 | M21: =IFERROR(IF(SEARCH(M$1,$J21)>0,1),0) -> 0 | N21: =IFERROR(IF(SEARCH(N$1,$J21)>0,1),0) -> 1 | O21: =SUM(K21:N21) -> 1 | P21: Propane | R21: 82 | S21: =IFERROR(IF(Q21<>"",Q21,R21*0.7457),"Unknown") -> 61.1474 | Y21: =X21*S21 -> 0 | Z21: =IFERROR(INDEX(EFs!B:B,MATCH(P21,EFs!A:A,0))*Dataset!Y21/1000,0) -> 0 | AA21: 33.387723 | AB21: -117.44476 | AC21: 0.5 | AD21: place | AI21: Camp Pendleton | AJ21: CA | AK21: San Diego County | AL21: 92055 | AM21: US | AN21: TIGER/LineÂ® dataset from the US Census Bureau
A22: APCD2003-PTO-971067 | B22: Active | C22: 40025 | D22: [34W] Registered Engine (Rule 12) | E22: USMC Base Marine Group Ops | F22: Air Quality Section | G22: Building 1133 Camp Pendleton, CA | H22: 92055 | I22: A | J22: EMERGENCY STANDBY ENGINE: MFR: FORD, MODEL LSG-875I-6005A, S/N 04781 A-05-RA, 132 BHP, FUEL: PROPANE, DRIVING A 76 KW GENERATOR. (971067-CCN-4/98)_x000D_ BLDG 1133 | K22: =IFERROR(IF(SEARCH(K$1,$J22)>0,1),0) -> 0 | L22: =IFERROR(IF(SEARCH(L$1,$J22)>0,1),0) -> 0 | M22: =IFERROR(IF(SEARCH(M$1,$J22)>0,1),0) -> 0 | N22: =IFERROR(IF(SEARCH(N$1,$J22)>0,1),0) -> 1 | O22: =SUM(K22:N22) -> 1 | P22: Propane | Q22: 76 | R22: 132 | S22: =IFERROR(IF(Q22<>"",Q22,R22*0.7457),"Unknown") -> 76 | Y22: =X22*S22 -> 0 | Z22: =IFERROR(INDEX(EFs!B:B,MATCH(P22,EFs!A:A,0))*Dataset!Y22/1000,0) -> 0 | AA22: 33.387723 | AB22: -117.44476 | AC22: 0.5 | AD22: place | AI22: Camp Pendleton | AJ22: CA | AK22: San Diego County | AL22: 92055 | AM22: US | AN22: TIGER/LineÂ® dataset from the US Census Bureau
A23: APCD2003-PTO-973507 | B23: Active | C23: 40025 | D23: [34W] Registered Engine (Rule 12) | E23: SD City Of Metro Wastewater Dept | F23: Civil Engineer | G23: 1795 Harbor Dr E San Diego, CA | H23: 92113 | I23: P | J23: CUMMINS NATURAL GAS ENGINE, MODEL G855, 220 HP, S/N 25208445. 973507AFS14JUN1999 071602AFS (CORRECT EQUIPMENT DESCRIPTION) | K23: =IFERROR(IF(SEARCH(K$1,$J23)>0,1),0) -> 0 | L23: =IFERROR(IF(SEARCH(L$1,$J23)>0,1),0) -> 0 | M23: =IFERROR(IF(SEARCH(M$1,$J23)>0,1),0) -> 1 | N23: =IFERROR(IF(SEARCH(N$1,$J23)>0,1),0) -> 0 | O23: =SUM(K23:N23) -> 1 | P23: Natural Gas | R23: 220 | S23: =IFERROR(IF(Q23<>"",Q23,R23*0.7457),"Unknown") -> 164.054 | T23: 44412 | U23: 232.50 | V23: 44412 | W23: 237.00 | X23: 4.5 | Y23: =X23*S23 -> 738.243 | Z23: =IFERROR(INDEX(EFs!B:B,MATCH(P23,EFs!A:A,0))*Dataset!Y23/1000,0) -> 0.5361532 | AA23: 32.699468 | AB23: -117.14955 | AC23: 1 | AD23: rooftop | AE23: 1795 | AF23: Harbor Dr | AI23: San Diego | AJ23: CA | AK23: San Diego County | AL23: 92113 | AM23: US | AN23: San Diego Geographic Information Source - JPA
A24: APCD2003-PTO-974008 | B24: Active | C24: 40025 | D24: [34W] Registered Engine (Rule 12) | E24: DEL CERRO CITY DEPT OF HIGHLANDS PUMP PLANT | G24: 6555 CRYSTALAIRE DR SAN DIEGO, CA | H24: 92120 | I24: J | J24: EMERGENCY GENERATOR: 240 BHP CUMMINS ENGINE, NATURAL GAS FIRED, MODEL GTA8.3 G5/GC2, S/N 45870458, WITH TURBOCHARGING AND AFTERCOOLING, DRIVING A150 KW GENERATOR. EAD 974008 2/9/00 | K24: =IFERROR(IF(SEARCH(K$1,$J24)>0,1),0) -> 0 | L24: =IFERROR(IF(SEARCH(L$1,$J24)>0,1),0) -> 0 | M24: =IFERROR(IF(SEARCH(M$1,$J24)>0,1),0) -> 1 | N24: =IFERROR(IF(SEARCH(N$1,$J24)>0,1),0) -> 0 | O24: =SUM(K24:N24) -> 1 | P24: Natural Gas | Q24: 150 | R24: 240 | S24: =IFERROR(IF(Q24<>"",Q24,R24*0.7457),"Unknown") -> 150 | T24: 44562 | U24: 691.70 | V24: 44562 | W24: 694.90 | X24: 3.2 | Y24: =X24*S24 -> 480 | Z24: =IFERROR(INDEX(EFs!B:B,MATCH(P24,EFs!A:A,0))*Dataset!Y24/1000,0) -> 0.34860275 | AA24: 32.788933 | AB24: -117.05578 | AC24: 1 | AD24: range_interpolation | AE24: 6555 | AF24: Crystalaire Dr | AI24: San Diego | AJ24: CA | AK24: San Diego County | AL24: 92120 | AM24: US | AN24: TIGER/LineÂ® dataset from the US Census Bureau
A25: APCD2003-PTO-974511 | B25: Active | C25: 40025 | D25: [34W] Registered Engine (Rule 12) | E25: USMC Base Public Utilities U29 | F25: Air Quality Section | G25: Building 610547 CAMP PENDLETON, CA | H25: 92055 | I25: A | J25: FORD PROPANE FIRED MODEL LSG875, GENERATOR S/N E6791J-001, 60 KW, 127.8 BHP. 145 PETERSON ST, SAN MATEO HOUSING 974511 AFS 27JAN2000 (BLDG 610547) | K25: =IFERROR(IF(SEARCH(K$1,$J25)>0,1),0) -> 0 | L25: =IFERROR(IF(SEARCH(L$1,$J25)>0,1),0) -> 0 | M25: =IFERROR(IF(SEARCH(M$1,$J25)>0,1),0) -> 0 | N25: =IFERROR(IF(SEARCH(N$1,$J25)>0,1),0) -> 1 | O25: =SUM(K25:N25) -> 1 | P25: Propane | Q25: 60 | R25: 127.8 | S25: =IFERROR(IF(Q25<>"",Q25,R25*0.7457),"Unknown") -> 60 | Y25: =X25*S25 -> 0 | Z25: =IFERROR(INDEX(EFs!B:B,MATCH(P25,EFs!A:A,0))*Dataset!Y25/1000,0) -> 0 | AA25: 33.387723 | AB25: -117.44476 | AC25: 0.5 | AD25: place | AI25: Camp Pendleton | AJ25: CA | AK25: San Diego County | AL25: 92055 | AM25: US | AN25: TIGER/LineÂ® dataset from the US Census Bureau
A26: APCD2003-PTO-974876 | B26: Active | C26: 40025 | D26: [34W] Registered Engine (Rule 12) | E26: USMC Base Marine Group Ops | F26: Air Quality Section | G26: Camp Pendleton Camp Pendleton, CA | H26: 92055 | I26: A | J26: EMERGENCY ENGINE GENERATOR, FUEL: NATURAL GAS, 495 HP, CUMMINS ENGINE, MODEL GTA19, S/N SN25247550. (BLDG. 210721) APPL# 974876 EFH 04/00 | K26: =IFERROR(IF(SEARCH(K$1,$J26)>0,1),0) -> 0 | L26: =IFERROR(IF(SEARCH(L$1,$J26)>0,1),0) -> 0 | M26: =IFERROR(IF(SEARCH(M$1,$J26)>0,1),0) -> 1 | N26: =IFERROR(IF(SEARCH(N$1,$J26)>0,1),0) -> 0 | O26: =SUM(K26:N26) -> 1 | P26: Natural Gas | R26: 495 | S26: =IFERROR(IF(Q26<>"",Q26,R26*0.7457),"Unknown") -> 369.1215 | Y26: =X26*S26 -> 0 | Z26: =IFERROR(INDEX(EFs!B:B,MATCH(P26,EFs!A:A,0))*Dataset!Y26/1000,0) -> 0 | AA26: 33.387723 | AB26: -117.44476 | AC26: 1 | AD26: place | AI26: Camp Pendleton | AJ26: CA | AK26: San Diego County | AL26: 92055 | AM26: US | AN26: TIGER/LineÂ® dataset from the US Census Bureau
A27: APCD2003-PTO-974877 | B27: Active | C27: 40025 | D27: [34H] California Certified Emergency Standby Engine | E27: USMC Base Marine Group Ops | F27: Air Quality Section | G27: Building 217201 Camp Pendleton, CA | H27: 92055 | I27: A | J27: Emergency Engine: Power Solutions ? Generac, Model: SG500, 777 BHP, NG fired, Engine Family No. LGNXB25.82C1, S/N 3005494043; certified with a 3-way catalyst and air-fuel ratio controller; driving a 500-kW electrical generator. | K27: =IFERROR(IF(SEARCH(K$1,$J27)>0,1),0) -> 0 | L27: =IFERROR(IF(SEARCH(L$1,$J27)>0,1),0) -> 0 | M27: =IFERROR(IF(SEARCH(M$1,$J27)>0,1),0) -> 0 | N27: =IFERROR(IF(SEARCH(N$1,$J27)>0,1),0) -> 0 | O27: =SUM(K27:N27) -> 0 | P27: Natural Gas | Q27: 500 | R27: 777 | S27: =IFERROR(IF(Q27<>"",Q27,R27*0.7457),"Unknown") -> 500 | Y27: =X27*S27 -> 0 | Z27: =IFERROR(INDEX(EFs!B:B,MATCH(P27,EFs!A:A,0))*Dataset!Y27/1000,0) -> 0 | AA27: 33.387723 | AB27: -117.44476 | AC27: 0.5 | AD27: place | AI27: Camp Pendleton | AJ27: CA | AK27: San Diego County | AL27: 92055 | AM27: US | AN27: TIGER/LineÂ® dataset from the US Census Bureau
A28: APCD2003-PTO-976368 | B28: Active | C28: 40025 | D28: [34W] Registered Engine (Rule 12) | E28: SD City Of Metro Wastewater Dept | G28: 2802 Bayside Walk San Diego, CA | H28: 92109 | I28: I | J28: EMERGENCY STANDBY ENGINE: FORD NATURAL GAS ENGINE, MODEL LSG-8751-6005-A, 165 BHP, DRIVING A GENERATOR. (976368-CCN-11/01) | K28: =IFERROR(IF(SEARCH(K$1,$J28)>0,1),0) -> 0 | L28: =IFERROR(IF(SEARCH(L$1,$J28)>0,1),0) -> 0 | M28: =IFERROR(IF(SEARCH(M$1,$J28)>0,1),0) -> 1 | N28: =IFERROR(IF(SEARCH(N$1,$J28)>0,1),0) -> 0 | O28: =SUM(K28:N28) -> 1 | P28: Natural Gas | R28: 165 | S28: =IFERROR(IF(Q28<>"",Q28,R28*0.7457),"Unknown") -> 123.0405 | Y28: =X28*S28 -> 0 | Z28: =IFERROR(INDEX(EFs!B:B,MATCH(P28,EFs!A:A,0))*Dataset!Y28/1000,0) -> 0 | AA28: 32.763541 | AB28: -117.25006 | AC28: 1 | AD28: range_interpolation | AE28: 2802 | AF28: Bayside Walk | AI28: San Diego | AJ28: CA | AK28: San Diego County | AL28: 92109 | AM28: US | AN28: TIGER/LineÂ® dataset from the US Census Bureau
A29: APCD2003-PTO-976369 | B29: Active | C29: 40025 | D29: [34W] Registered Engine (Rule 12) | E29: SD City Of Metro Wastewater Dept | G29: 102 Fern Glen La Jolla, CA | H29: 92037 | I29: I | J29: EMERGENCY STANDBY ENGINE: GENERAC NATURAL GAS ENGINE, MODEL 7.4L, S/N A4350, 165 BHP, DRIVING A GENERATOR. (976369-CCN-11/01) | K29: =IFERROR(IF(SEARCH(K$1,$J29)>0,1),0) -> 0 | L29: =IFERROR(IF(SEARCH(L$1,$J29)>0,1),0) -> 0 | M29: =IFERROR(IF(SEARCH(M$1,$J29)>0,1),0) -> 1 | N29: =IFERROR(IF(SEARCH(N$1,$J29)>0,1),0) -> 0 | O29: =SUM(K29:N29) -> 1 | P29: Natural Gas | R29: 165 | S29: =IFERROR(IF(Q29<>"",Q29,R29*0.7457),"Unknown") -> 123.0405 | T29: 44350 | U29: 34.60 | V29: 44350 | W29: 44.00 | X29: 9.4 | Y29: =X29*S29 -> 1156.5807 | Z29: =IFERROR(INDEX(EFs!B:B,MATCH(P29,EFs!A:A,0))*Dataset!Y29/1000,0) -> 0.83997335 | AA29: 32.834131 | AB29: -117.28134 | AC29: 1 | AD29: range_interpolation | AE29: 102 | AF29: Fern Gln | AI29: LA Jolla | AJ29: CA | AK29: San Diego County | AL29: 92037 | AM29: US | AN29: TIGER/LineÂ® dataset from the US Census Bureau
A30: APCD2003-PTO-976371 | B30: Active | C30: 40025 | D30: [34W] Registered Engine (Rule 12) | E30: SD City Of Metro Wastewater Dept | G30: 5995 Camino De La Costa La Jolla, CA | H30: 92037 | I30: I | J30: EMERGENCY STANDBY ENGINE: FORD NATURAL GAS ENGINE, MODEL LSG-8751-6005-A, S/N 07413, 90 BHP, DRIVING A GENERATOR. (976371-CCN-11/01) | K30: =IFERROR(IF(SEARCH(K$1,$J30)>0,1),0) -> 0 | L30: =IFERROR(IF(SEARCH(L$1,$J30)>0,1),0) -> 0 | M30: =IFERROR(IF(SEARCH(M$1,$J30)>0,1),0) -> 1 | N30: =IFERROR(IF(SEARCH(N$1,$J30)>0,1),0) -> 0 | O30: =SUM(K30:N30) -> 1 | P30: Natural Gas | R30: 90 | S30: =IFERROR(IF(Q30<>"",Q30,R30*0.7457),"Unknown") -> 67.113 | T30: 44350 | U30: 256.20 | V30: 44350 | W30: 263.20 | X30: 7 | Y30: =X30*S30 -> 469.791 | Z30: =IFERROR(INDEX(EFs!B:B,MATCH(P30,EFs!A:A,0))*Dataset!Y30/1000,0) -> 0.3411884 | AA30: 32.81874 | AB30: -117.27591 | AC30: 0.9 | AD30: nearest_rooftop_match | AE30: 5998 | AF30: Camino De La Costa | AI30: LA Jolla | AJ30: CA | AK30: San Diego County | AL30: 92037 | AM30: US | AN30: San Diego Geographic Information Source - JPA
A31: APCD2003-PTO-976375 | B31: Active | C31: 40025 | D31: [34W] Registered Engine (Rule 12) | E31: SD City Of Metro Wastewater Dept | G31: 1840 Mission Bay Dr W San Diego, CA | H31: 92109 | I31: I | J31: EMERGENCY STANDBY ENGINE: FORD NATURAL GAS ENGINE, MODEL LSG-8751-6005-A, 135 BHP, DRIVING A GENERATOR, (976375-CCN-11/01). Serial number: 00937 G-12-RL | K31: =IFERROR(IF(SEARCH(K$1,$J31)>0,1),0) -> 0 | L31: =IFERROR(IF(SEARCH(L$1,$J31)>0,1),0) -> 0 | M31: =IFERROR(IF(SEARCH(M$1,$J31)>0,1),0) -> 1 | N31: =IFERROR(IF(SEARCH(N$1,$J31)>0,1),0) -> 0 | O31: =SUM(K31:N31) -> 1 | P31: Natural Gas | R31: 135 | S31: =IFERROR(IF(Q31<>"",Q31,R31*0.7457),"Unknown") -> 100.6695 | Y31: =X31*S31 -> 0 | Z31: =IFERROR(INDEX(EFs!B:B,MATCH(P31,EFs!A:A,0))*Dataset!Y31/1000,0) -> 0 | AA31: 32.764046 | AB31: -117.23305 | AC31: 0.9 | AD31: range_interpolation | AE31: 1840 | AF31: W Mission Bay Dr | AI31: San Diego | AJ31: CA | AK31: San Diego County | AL31: 92109 | AM31: US | AN31: TIGER/LineÂ® dataset from the US Census Bureau
A32: APCD2003-PTO-976376 | B32: Active | C32: 40025 | D32: [34H] California Certified Emergency Standby Engine | E32: City of SD, Public Utilities Department | F32: Facility Manager SPS 31 | G32: 6652 CALLE DE LINEA SAN DIEGO, CA | H32: 92154 | I32: S | J32: Emergency Engine: Kohler, Model: KG6208TAHD 6.2L, 202 BHP, Natural Gas fired, Engine Family No. LKHXB06.2HNG, S/N OE20201586; certified with an electronic air to fuel controller and TWC driving a 100-kW generator. | K32: =IFERROR(IF(SEARCH(K$1,$J32)>0,1),0) -> 0 | L32: =IFERROR(IF(SEARCH(L$1,$J32)>0,1),0) -> 0 | M32: =IFERROR(IF(SEARCH(M$1,$J32)>0,1),0) -> 1 | N32: =IFERROR(IF(SEARCH(N$1,$J32)>0,1),0) -> 0 | O32: =SUM(K32:N32) -> 1 | P32: Natural Gas | Q32: 100 | R32: 202 | S32: =IFERROR(IF(Q32<>"",Q32,R32*0.7457),"Unknown") -> 100 | T32: 44406 | U32: 0.80 | V32: 44776 | W32: 19.20 | X32: 18.4 | Y32: =X32*S32 -> 1840 | Z32: =IFERROR(INDEX(EFs!B:B,MATCH(P32,EFs!A:A,0))*Dataset!Y32/1000,0) -> 1.3363105 | AA32: 32.548779 | AB32: -116.99539 | AC32: 0.7 | AD32: nearest_rooftop_match | AE32: 6754 | AF32: Calle De Linea | AI32: San Diego | AJ32: CA | AK32: San Diego County | AL32: 92154 | AM32: US | AN32: San Diego Geographic Information Source - JPA
A33: APCD2003-PTO-976377 | B33: Active | C33: 40025 | D33: [34W] Registered Engine (Rule 12) | E33: SD City Of Metro Wastewater Dept | G33: 3214 Bayside Walk San Diego, CA | H33: 92109 | I33: I | J33: EMERGENCY STANDBY ENGINE: FORD NATURAL GAS ENGINE, MODEL LSG-8751-6005-A, S/N 17448, 135 BHP, DRIVING A GENERATOR. (976377-CCN-11/01) | K33: =IFERROR(IF(SEARCH(K$1,$J33)>0,1),0) -> 0 | L33: =IFERROR(IF(SEARCH(L$1,$J33)>0,1),0) -> 0 | M33: =IFERROR(IF(SEARCH(M$1,$J33)>0,1),0) -> 1 | N33: =IFERROR(IF(SEARCH(N$1,$J33)>0,1),0) -> 0 | O33: =SUM(K33:N33) -> 1 | P33: Natural Gas | R33: 135 | S33: =IFERROR(IF(Q33<>"",Q33,R33*0.7457),"Unknown") -> 100.6695 | Y33: =X33*S33 -> 0 | Z33: =IFERROR(INDEX(EFs!B:B,MATCH(P33,EFs!A:A,0))*Dataset!Y33/1000,0) -> 0 | AA33: 32.772405 | AB33: -117.2498 | AC33: 1 | AD33: range_interpolation | AE33: 3214 | AF33: Bayside Walk | AI33: San Diego | AJ33: CA | AK33: San Diego County | AL33: 92109 | AM33: US | AN33: TIGER/LineÂ® dataset from the US Census Bureau
A34: APCD2003-PTO-976378 | B34: Active | C34: 40025 | D34: [34W] Registered Engine (Rule 12) | E34: SD City Of Metro Wastewater Dept | G34: 5060 Pt Loma Blvd W San Diego, CA | H34: 92107 | I34: I | J34: EMERGENCY STANDBY ENGINE: FORD NATURAL GAS ENGINE, MODEL LSG-8751-6005-A, S/N 15291, 135 BHP, DRIVING A GENERATOR. (976378-CCN-11/01) | K34: =IFERROR(IF(SEARCH(K$1,$J34)>0,1),0) -> 0 | L34: =IFERROR(IF(SEARCH(L$1,$J34)>0,1),0) -> 0 | M34: =IFERROR(IF(SEARCH(M$1,$J34)>0,1),0) -> 1 | N34: =IFERROR(IF(SEARCH(N$1,$J34)>0,1),0) -> 0 | O34: =SUM(K34:N34) -> 1 | P34: Natural Gas | R34: 135 | S34: =IFERROR(IF(Q34<>"",Q34,R34*0.7457),"Unknown") -> 100.6695 | T34: 44350 | U34: 278.60 | V34: 44350 | W34: 282.70 | X34: 4.1 | Y34: =X34*S34 -> 412.74495 | Z34: =IFERROR(INDEX(EFs!B:B,MATCH(P34,EFs!A:A,0))*Dataset!Y34/1000,0) -> 0.29975838 | AA34: 32.724103 | AB34: -117.17091 | AC34: 0.5 | AD34: place | AI34: San Diego | AJ34: CA | AK34: San Diego County | AL34: 92101 | AM34: US | AN34: TIGER/LineÂ® dataset from the US Census Bureau
A35: APCD2003-PTO-976531 | B35: Active | C35: 40025 | D35: [34H] California Certified Emergency Standby Engine | E35: Union Bank Of California | F35: Property Manager | G35: 8954 Rio San Diego San Diego, CA | H35: 92108 | I35: M | J35: EMERGENCY STANDBY ENGINE: CATERPILLAR DIESEL ENGINE, MODEL 3406, S/N 1LSO1576, RATED AT 519 BHP, EPA TIER 1 CERTIFIED OF ENGINE FAMILY NUMBER 1CPXL14.6ESK, EQUIPPED WITH TURBOCHARGER, DRIVING A 350 KW GENERATOR (976531-CCN-10/02) 17CCR93115SJE8/06 | K35: =IFERROR(IF(SEARCH(K$1,$J35)>0,1),0) -> 1 | L35: =IFERROR(IF(SEARCH(L$1,$J35)>0,1),0) -> 0 | M35: =IFERROR(IF(SEARCH(M$1,$J35)>0,1),0) -> 0 | N35: =IFERROR(IF(SEARCH(N$1,$J35)>0,1),0) -> 0 | O35: =SUM(K35:N35) -> 1 | P35: Diesel | Q35: 350 | R35: 519 | S35: =IFERROR(IF(Q35<>"",Q35,R35*0.7457),"Unknown") -> 350 | Y35: =X35*S35 -> 0 | Z35: =IFERROR(INDEX(EFs!B:B,MATCH(P35,EFs!A:A,0))*Dataset!Y35/1000,0) -> 0 | AA35: 32.776536 | AB35: -117.13599 | AC35: 1 | AD35: rooftop | AE35: 8954 | AF35: Rio San Diego Dr | AI35: San Diego | AJ35: CA | AK35: San Diego County | AL35: 92108 | AM35: US | AN35: San Diego Geographic Information Source - JPA
A36: APCD2003-PTO-976877 | B36: Active | C36: 40025 | D36: [34H] California Certified Emergency Standby Engine | E36: Fallbrook PUD - Shady Lane Lift Station | F36: Soleil Develle | G36: 739 Shady Lane Fallbrook, CA | H36: 92028 | I36: A | J36: Emergency Diesel Engine Generator: Kohler, Model KDI3404TCR rated at 94 bhp, S/N 4819702450 , Engine Family: JKHXL3.36TCR, EPA Tier 3 certified engine; driving an 60-kW emergency electrical generator. | K36: =IFERROR(IF(SEARCH(K$1,$J36)>0,1),0) -> 1 | L36: =IFERROR(IF(SEARCH(L$1,$J36)>0,1),0) -> 0 | M36: =IFERROR(IF(SEARCH(M$1,$J36)>0,1),0) -> 0 | N36: =IFERROR(IF(SEARCH(N$1,$J36)>0,1),0) -> 0 | O36: =SUM(K36:N36) -> 1 | P36: Diesel | Q36: 60 | R36: 94 | S36: =IFERROR(IF(Q36<>"",Q36,R36*0.7457),"Unknown") -> 60 | T36: 44406 | U36: 50.10 | V36: 44406 | W36: 62.80 | X36: 12.7 | Y36: =X36*S36 -> 762 | Z36: =IFERROR(INDEX(EFs!B:B,MATCH(P36,EFs!A:A,0))*Dataset!Y36/1000,0) -> 0.69219541 | AA36: 33.389361 | AB36: -117.25547 | AC36: 1 | AD36: rooftop | AE36: 739 | AF36: Shady Ln | AI36: Fallbrook | AJ36: CA | AK36: San Diego County | AL36: 92028 | AM36: US | AN36: Sandoval
A37: APCD2003-PTO-977041 | B37: Active | C37: 40025 | D37: [34W] Registered Engine (Rule 12) | E37: Ramona Municipal Water District | F37: Tom McKernan | G37: 16424 Woodson DR N Ramona, CA | H37: 92065 | I37: F | J37: EMERGENCY GENERATOR FORD MODEL CSG-6491-6005-F S/N 01199-G-22-RB. HP RATING 95. PROPANE FUELED. | K37: =IFERROR(IF(SEARCH(K$1,$J37)>0,1),0) -> 0 | L37: =IFERROR(IF(SEARCH(L$1,$J37)>0,1),0) -> 0 | M37: =IFERROR(IF(SEARCH(M$1,$J37)>0,1),0) -> 0 | N37: =IFERROR(IF(SEARCH(N$1,$J37)>0,1),0) -> 1 | O37: =SUM(K37:N37) -> 1 | P37: Propane | R37: 95 | S37: =IFERROR(IF(Q37<>"",Q37,R37*0.7457),"Unknown") -> 70.8415 | T37: 44532 | U37: 632.70 | V37: 44532 | W37: 639.30 | X37: 6.6 | Y37: =X37*S37 -> 467.5539 | Z37: =IFERROR(INDEX(EFs!B:B,MATCH(P37,EFs!A:A,0))*Dataset!Y37/1000,0) -> 0.38521766 | AA37: 33.015616 | AB37: -116.95938 | AC37: 0.95 | AD37: rooftop | AE37: 16424 | AF37: N Woodson Dr | AI37: Ramona | AJ37: CA | AK37: San Diego County | AL37: 92065 | AM37: US | AN37: San Diego Geographic Information Source - JPA
A38: APCD2003-PTO-977043 | B38: Active | C38: 40025 | D38: [34W] Registered Engine (Rule 12) | E38: Ramona Municipal Water District | F38: Facility Manager | G38: 24462 San Vicente RD Ramona, CA | H38: 92065 | I38: F | J38: EMERGENCY GENERATOR GENERAC. MODEL : CA3797. S/N: 2039349. PROPANE FUELED._x000D_ENGINE MODEL NUMBER 4.3L, S/N A3797. | K38: =IFERROR(IF(SEARCH(K$1,$J38)>0,1),0) -> 0 | L38: =IFERROR(IF(SEARCH(L$1,$J38)>0,1),0) -> 0 | M38: =IFERROR(IF(SEARCH(M$1,$J38)>0,1),0) -> 0 | N38: =IFERROR(IF(SEARCH(N$1,$J38)>0,1),0) -> 1 | O38: =SUM(K38:N38) -> 1 | P38: Propane | R38: Unknown | S38: =IFERROR(IF(Q38<>"",Q38,R38*0.7457),"Unknown") -> Unknown | T38: 44532 | U38: 443.40 | V38: 44532 | W38: 449.00 | X38: 5.6 | Y38: =X38*S38 -> #VALUE! | Z38: =IFERROR(INDEX(EFs!B:B,MATCH(P38,EFs!A:A,0))*Dataset!Y38/1000,0) -> 0 | AA38: 33.000872 | AB38: -116.80008 | AC38: 1 | AD38: rooftop | AE38: 24462 | AF38: San Vicente Rd | AI38: Ramona | AJ38: CA | AK38: San Diego County | AL38: 92065 | AM38: US | AN38: San Diego Geographic Information Source - JPA
A39: APCD2003-PTO-977127 | B39: Active | C39: 40025 | D39: [34C] Emergency Standby Engine | E39: SD City Of | F39: Facility Manager | G39: 6689 Neptune Place San Diego, CA | H39: 92037 | I39: I | J39: EMERGENCY STANDBY ENGINE: GENERAL MOTORS ENGINE, NATURAL GAS FUELED, MODEL VORTEC 8.1 LITER, S/N 8.1L-05331, RATED AT 136 BHP, EQUIPPED WITH THREE-WAY CATALYTIC CONVERTER, DRIVING AN 80 KW GENERATOR. (977127-CCN-9/03) | K39: =IFERROR(IF(SEARCH(K$1,$J39)>0,1),0) -> 0 | L39: =IFERROR(IF(SEARCH(L$1,$J39)>0,1),0) -> 0 | M39: =IFERROR(IF(SEARCH(M$1,$J39)>0,1),0) -> 1 | N39: =IFERROR(IF(SEARCH(N$1,$J39)>0,1),0) -> 0 | O39: =SUM(K39:N39) -> 1 | P39: Natural Gas | Q39: 80 | R39: 136 | S39: =IFERROR(IF(Q39<>"",Q39,R39*0.7457),"Unknown") -> 80 | T39: 44350 | U39: 260.40 | V39: 44350 | W39: 264.10 | X39: 3.7 | Y39: =X39*S39 -> 296 | Z39: =IFERROR(INDEX(EFs!B:B,MATCH(P39,EFs!A:A,0))*Dataset!Y39/1000,0) -> 0.21497169 | AA39: 32.828222 | AB39: -117.2801 | AC39: 0.9 | AD39: range_interpolation | AE39: 6689 | AF39: Neptune Pl | AI39: LA Jolla | AJ39: CA | AK39: San Diego County | AL39: 92037 | AM39: US | AN39: TIGER/LineÂ® dataset from the US Census Bureau
A40: APCD2003-PTO-977370 | B40: Active | C40: 40025 | D40: [34W] Registered Engine (Rule 12) | E40: Rainbow Municipal Water District | F40: Jeff Stacy | G40: 4198 Lake Circle Dr Fallbrook, CA | H40: 92028 | I40: A | J40: EMERGENCY ENGINE: MFR: HINO, MODEL: EK130, SERIAL: A10615, Generac serial number 76815, FUEL: PROPANE, _x000D_DISPLACEMENT: 13.3 LITERS, CONFIGURATION: INLINE 6 CYLINDER, HP RATING= 177.5, _x000D_FOR A 125 KW GENERATOR (MFR: GENERAC; MODEL: 3285B1263B, S/N: AD205193SPK) SEWER LIFT STATION #5. | K40: =IFERROR(IF(SEARCH(K$1,$J40)>0,1),0) -> 0 | L40: =IFERROR(IF(SEARCH(L$1,$J40)>0,1),0) -> 0 | M40: =IFERROR(IF(SEARCH(M$1,$J40)>0,1),0) -> 0 | N40: =IFERROR(IF(SEARCH(N$1,$J40)>0,1),0) -> 1 | O40: =SUM(K40:N40) -> 1 | P40: Propane | Q40: 125 | R40: 177.5 | S40: =IFERROR(IF(Q40<>"",Q40,R40*0.7457),"Unknown") -> 125 | Y40: =X40*S40 -> 0 | Z40: =IFERROR(INDEX(EFs!B:B,MATCH(P40,EFs!A:A,0))*Dataset!Y40/1000,0) -> 0 | AA40: 33.324158 | AB40: -117.15668 | AC40: 1 | AD40: range_interpolation | AE40: 4198 | AF40: Lake Circle Dr | AI40: Fallbrook | AJ40: CA | AK40: San Diego County | AL40: 92028 | AM40: US | AN40: TIGER/LineÂ® dataset from the US Census Bureau
...

Sheet EFs
A1: Fuel | B1: CO2 Mt/MWh
A2: Diesel | B2: 0.90839292
A3: Natural Gas | B3: 0.72625572
A4: Gasoline | B4: 0.79502531
A5: Oil | B5: 0.93205218
A6: LPG | B6: 0.99271569
A7: Propane | B7: 0.8239

Sheet Summary
A1: Fuel | B1: Count of Gensets | C1: Average Capacity (kW) | D1: Total Capacity (MW) | E1: Estimated Generation (MWh) | F1: Average Operational Hours | G1: Total Operational Hours
A2: Diesel | B2: =COUNTIFS(Dataset!P:P,A2,Dataset!B:B,"Active") -> 2874 | C2: =AVERAGEIFS(Dataset!S:S,Dataset!P:P,A2,Dataset!S:S,">0",Dataset!S:S,"<>Unknown",Dataset!B:B,"Active") -> 355.71183 | D2: =SUMIFS(Dataset!S:S,Dataset!P:P,A2,Dataset!S:S,">0",Dataset!B:B,"Active")/1000 -> 1018.0473 | E2: =SUMIFS(Dataset!Y:Y,Dataset!P:P,A2,Dataset!Y:Y,">0",Dataset!B:B,"Active")/1000 -> 9405.6979 | F2: =AVERAGEIFS(Dataset!X:X,Dataset!P:P,A2,Dataset!X:X,">0",Dataset!B:B,"Active") -> 12.407365 | G2: =SUMIFS(Dataset!X:X,Dataset!P:P,A2,Dataset!X:X,">0",Dataset!B:B,"Active") -> 25335.84
A3: Propane | B3: =COUNTIFS(Dataset!P:P,A3,Dataset!B:B,"Active") -> 130 | C3: =AVERAGEIFS(Dataset!S:S,Dataset!P:P,A3,Dataset!S:S,">0",Dataset!S:S,"<>Unknown",Dataset!B:B,"Active") -> 77.07996 | D3: =SUMIFS(Dataset!S:S,Dataset!P:P,A3,Dataset!S:S,">0",Dataset!B:B,"Active")/1000 -> 9.8662348 | E3: =SUMIFS(Dataset!Y:Y,Dataset!P:P,A3,Dataset!Y:Y,">0",Dataset!B:B,"Active")/1000 -> 152.88678 | F3: =AVERAGEIFS(Dataset!X:X,Dataset!P:P,A3,Dataset!X:X,">0",Dataset!B:B,"Active") -> 24.353977 | G3: =SUMIFS(Dataset!X:X,Dataset!P:P,A3,Dataset!X:X,">0",Dataset!B:B,"Active") -> 2143.15
A4: Natural Gas | B4: =COUNTIFS(Dataset!P:P,A4,Dataset!B:B,"Active") -> 228 | C4: =AVERAGEIFS(Dataset!S:S,Dataset!P:P,A4,Dataset!S:S,">0",Dataset!S:S,"<>Unknown",Dataset!B:B,"Active") -> 120.58276 | D4: =SUMIFS(Dataset!S:S,Dataset!P:P,A4,Dataset!S:S,">0",Dataset!B:B,"Active")/1000 -> 27.251703 | E4: =SUMIFS(Dataset!Y:Y,Dataset!P:P,A4,Dataset!Y:Y,">0",Dataset!B:B,"Active")/1000 -> 209.95033 | F4: =AVERAGEIFS(Dataset!X:X,Dataset!P:P,A4,Dataset!X:X,">0",Dataset!B:B,"Active") -> 11.698659 | G4: =SUMIFS(Dataset!X:X,Dataset!P:P,A4,Dataset!X:X,">0",Dataset!B:B,"Active") -> 1918.58
A5: LPG | B5: =COUNTIFS(Dataset!P:P,A5,Dataset!B:B,"Active") -> 22 | C5: =AVERAGEIFS(Dataset!S:S,Dataset!P:P,A5,Dataset!S:S,">0",Dataset!S:S,"<>Unknown",Dataset!B:B,"Active") -> 68.097827 | D5: =SUMIFS(Dataset!S:S,Dataset!P:P,A5,Dataset!S:S,">0",Dataset!B:B,"Active")/1000 -> 1.4981522 | E5: =SUMIFS(Dataset!Y:Y,Dataset!P:P,A5,Dataset!Y:Y,">0",Dataset!B:B,"Active")/1000 -> 37.040696 | F5: =AVERAGEIFS(Dataset!X:X,Dataset!P:P,A5,Dataset!X:X,">0",Dataset!B:B,"Active") -> 64.996 | G5: =SUMIFS(Dataset!X:X,Dataset!P:P,A5,Dataset!X:X,">0",Dataset!B:B,"Active") -> 974.94
A6: Gasoline | B6: =COUNTIFS(Dataset!P:P,A6,Dataset!B:B,"Active") -> 2 | C6: =AVERAGEIFS(Dataset!S:S,Dataset!P:P,A6,Dataset!S:S,">0",Dataset!S:S,"<>Unknown",Dataset!B:B,"Active") -> 38.0307 | D6: =SUMIFS(Dataset!S:S,Dataset!P:P,A6,Dataset!S:S,">0",Dataset!B:B,"Active")/1000 -> 0.0380307 | E6: =SUMIFS(Dataset!Y:Y,Dataset!P:P,A6,Dataset!Y:Y,">0",Dataset!B:B,"Active")/1000 -> 1.9661872 | F6: =AVERAGEIFS(Dataset!X:X,Dataset!P:P,A6,Dataset!X:X,">0",Dataset!B:B,"Active") -> 28.05 | G6: =SUMIFS(Dataset!X:X,Dataset!P:P,A6,Dataset!X:X,">0",Dataset!B:B,"Active") -> 56.1
A7: Unknown | B7: =COUNTIFS(Dataset!P:P,A7,Dataset!B:B,"Active") -> 108 | C7: =AVERAGEIFS(Dataset!S:S,Dataset!P:P,A7,Dataset!S:S,">0",Dataset!S:S,"<>Unknown",Dataset!B:B,"Active") -> 287.95271 | D7: =SUMIFS(Dataset!S:S,Dataset!P:P,A7,Dataset!S:S,">0",Dataset!B:B,"Active")/1000 -> 30.235034 | E7: =SUMIFS(Dataset!Y:Y,Dataset!P:P,A7,Dataset!Y:Y,">0",Dataset!B:B,"Active")/1000 -> 215.73179 | F7: =AVERAGEIFS(Dataset!X:X,Dataset!P:P,A7,Dataset!X:X,">0",Dataset!B:B,"Active") -> 10.724247 | G7: =SUMIFS(Dataset!X:X,Dataset!P:P,A7,Dataset!X:X,">0",Dataset!B:B,"Active") -> 782.87
A9: Total | B9: =SUM(B2:B7) -> 3364 | C9: =AVERAGEIFS(Dataset!S:S,Dataset!S:S,">0",Dataset!B:B,"Active") -> 325.04079 | D9: =SUM(D2:D7) -> 1086.9364 | E9: =SUMIFS(Dataset!Y:Y,Dataset!Y:Y,">0",Dataset!B:B,"Active")/1000 -> 10023.274 | F9: =AVERAGEIFS(Dataset!X:X,Dataset!X:X,">0",Dataset!B:B,"Active") -> 13.092064 | G9: =SUM(G2:G7) -> 31211.48
D12: # of gensets with no listed capacity | F12: # of gensets not reporting hours
D13: =COUNTIFS(Dataset!S:S,"Unknown",Dataset!B:B,"Active") -> 20 | F13: =COUNTIFS(Dataset!X1:X4145,"",Dataset!B1:B4145,"Active") -> 838 | G13: =F13/3364 -> 0.2491082
D14: Additional MW if they are average sized | F14: Additional operating hours if avg.
D15: =D13*C9/1000 -> 6.5008159 | F15: =F9*F13 -> 10971.149
